<?xml version="1.0"?>
<robot name="dfrobot">
  <link name="base_link">
    <visual>  
      <material name="body_color">
        <color rgba="1 0.2 0 0.9" />
      </material>
      <geometry>
        <box size="0.134 .136 .002"/>
      </geometry>
    </visual>
  </link>
  
 <link name="left_board">
    <visual>
      <geometry>
        <box size="0.15 .002 .08"/>
      </geometry>
     </visual>
  </link>
  <joint name="base_to_left_board" type="fixed">
    <parent link="base_link"/>
    <child link="left_board"/>
    <origin xyz="-0.047 0.069 0.007"/> //z: base_link to the ground
  </joint>
  
  <link name="right_board">
    <visual>
      <geometry>
        <box size="0.15 .002 .08"/>
      </geometry>
     </visual>
  </link>

  <joint name="base_to_right_board" type="fixed">
    <parent link="base_link"/>
    <child link="right_board"/>
    <origin xyz="-0.047 -0.069 0.007"/>
  </joint>
  
  <link name="top_board">
    <visual>
      <material name="body_color"/>
      <geometry>
        <box size="0.15 .136 .002"/>
      </geometry>
     </visual>
  </link>
  <joint name="left_board_to_top_board" type="fixed">
    <parent link="left_board"/>
    <child link="top_board"/>
    <origin xyz="0.0 -0.069 0.04"/> //z: base_link to the ground
  </joint>
  
  <joint name="base_to_front_board" type="fixed">
    <parent link="base_link"/>
    <child link="front_board"/>
    <origin xyz="0.047 0.0 0.027" rpy="0 1.0178 0" />
  </joint>
  
  <link name="front_board">
    <visual>
      <geometry>
        <box size="0.07 .136 .002"/>
      </geometry>
     </visual>
  </link>
  
  <joint name="right_board_to_master_right_axix" type="continuous">
    <parent link="right_board"/>
    <child link="tyer_master_right_axis"/>
    <axis xyz="0 0 1"/> 
    <origin rpy="1.57075 0 0" xyz="-0.005 -0.016 0.026"/>
    <limit effort="100" velocity="100"/> 
    <joint_properties damping="0.0" friction="0.0"/>
  </joint>

  <link name="tyer_master_right_axis">
    <visual>
      <geometry>
       <cylinder length=".03" radius="0.003"/>
      </geometry>
      <material name="yellow">
          <color rgba="1 1 0 1"/>
      </material>  
    </visual>
  </link>

  <joint name="left_board_to_master_left_axis" type="continuous">
    <axis xyz="0 0 1"/> 
    <origin rpy="1.57075 0 0" xyz="-0.005 0.016 0.026"/>
    <limit effort="100" velocity="100"/> 
    <joint_properties damping="0.0" friction="0.0"/>
    <parent link="left_board"/>
    <child link="tyer_master_left_axis"/>
  </joint>
  
  <link name="tyer_master_left_axis">
    <visual>
      <geometry>
       <cylinder length=".03" radius="0.003"/>
      </geometry>
      <material name="yellow">
          <color rgba="1 1 0 1"/>
      </material>  
    </visual>
  </link>

  <link name="tyer_master_right_motor">
    <visual>
      <origin rpy="0 0 0" xyz="-0.015 0.0 0.0"/>
      <geometry>
	<box size="0.047 .048 .026"/>
      </geometry>
      <material name="black">
          <color rgba="0 0 0 1"/>
      </material>  
    </visual>
  </link>

  <joint name="right_leg_to_master_right_motor" type="fixed">
    <axis xyz="0 0 1"/> 
    <parent link="right_board"/>
    <child link="tyer_master_right_motor"/>
    <origin rpy="0 0 0" xyz="-0.005 0.025 0.026"/>
    <limit effort="100" velocity="100"/> 
    <joint_properties damping="0.0" friction="0.0"/>
  </joint>

  <link name="tyer_master_left_motor">
    <visual>
      <origin rpy="0 0 0" xyz="-0.015 0.0 0.0"/>
      <geometry>
       <box size="0.047 .048 .026"/>
      </geometry>
      <material name="black">
          <color rgba="0 0 0 1"/>
      </material>  
    </visual>
  </link>

  <joint name="left_leg_to_master_left_motor" type="fixed">
    <axis xyz="0 0 1"/> 
    <parent link="left_board"/>
    <child link="tyer_master_left_motor"/>
    <origin rpy="0 0 0" xyz="-0.005 -0.025 0.026"/>
    <limit effort="100" velocity="100"/> 
    <joint_properties damping="0.0" friction="0.0"/>
  </joint>
  
  

  
  <!--add slave axix: 4 on a side, 1:front to 4:back-->
  
  <link name="tyer_slave_right_axis2">
    <visual>
      <geometry>
	<cylinder length=".03" radius="0.003"/>
      </geometry>
      <material name="yellow">
          <color rgba="1 1 0 1"/>
      </material>  
    </visual>
  </link>

  <joint name="right_leg_to_slave_right_axix2" type="continuous">
    <axis xyz="0 0 1"/> 
    <parent link="right_board"/>
    <child link="tyer_slave_right_axis2"/>
    <origin rpy="1.57075 0 0" xyz="0.0 -0.016 -0.03"/>
    <limit effort="100" velocity="100"/> 
    <joint_properties damping="0.0" friction="0.0"/>
  </joint>
  
  <link name="tyer_slave_left_axis2">
    <visual>
      <geometry>
       <cylinder length=".03" radius="0.003"/>
      </geometry>
      <material name="yellow">
          <color rgba="1 1 0 1"/>
      </material>  
    </visual>
  </link>

  <joint name="left_leg_to_slave_left_axix2" type="continuous">
    <axis xyz="0 0 1"/> 
    <parent link="left_board"/>
    <child link="tyer_slave_left_axis2"/>
    <origin rpy="1.57075 0 0" xyz="0.0 0.016 -0.03"/>
    <limit effort="100" velocity="100"/> 
    <joint_properties damping="0.0" friction="0.0"/>
  </joint>

  <link name="tyer_slave_right_axis3">
    <visual>
      <geometry>
	<cylinder length=".03" radius="0.003"/>
      </geometry>
      <material name="yellow">
          <color rgba="1 1 0 1"/>
      </material>  
    </visual>
  </link>

  <joint name="right_leg_to_slave_right_axix3" type="continuous">
    <axis xyz="0 0 1"/> 
    <parent link="right_board"/>
    <child link="tyer_slave_right_axis3"/>
    <origin rpy="1.57075 0 0" xyz="0.06 -0.016 -0.03"/>
    <limit effort="100" velocity="100"/> 
    <joint_properties damping="0.0" friction="0.0"/>
  </joint>

  <link name="tyer_slave_left_axis3">
    <visual>
      <geometry>
       <cylinder length=".03" radius="0.003"/>
      </geometry>
      <material name="yellow">
          <color rgba="1 1 0 1"/>
      </material>  
    </visual>
  </link>

  <joint name="left_leg_to_slave_left_axix3" type="continuous">
    <axis xyz="0 0 1"/> 
    <parent link="left_board"/>
    <child link="tyer_slave_left_axis3"/>
    <origin rpy="1.57075 0 0" xyz="0.06 0.016 -0.03"/>
    <limit effort="100" velocity="100"/> 
    <joint_properties damping="0.0" friction="0.0"/>
  </joint>
  
  <link name="tyer_slave_right_axis4">
    <visual>
      <geometry>
       <cylinder length=".03" radius="0.003"/>
      </geometry>
      <material name="yellow">
          <color rgba="1 1 0 1"/>
      </material>  
    </visual>
  </link>

  <joint name="right_leg_to_slave_right_axix4" type="continuous">
    <axis xyz="0 0 1"/> 
    <parent link="right_board"/>
    <child link="tyer_slave_right_axis4"/>
    <origin rpy="1.57075 0 0" xyz="-0.06 -0.016 -0.03"/>
    <limit effort="100" velocity="100"/> 
    <joint_properties damping="0.0" friction="0.0"/>
  </joint>  


  <link name="tyer_slave_left_axis4">
    <visual>
      <geometry>
       <cylinder length=".03" radius="0.003"/>
      </geometry>
      <material name="yellow">
          <color rgba="1 1 0 1"/>
      </material>  
    </visual>
  </link>

  <joint name="right_leg_to_slave_left_axix4" type="continuous">
    <axis xyz="0 0 1"/> 
    <parent link="left_board"/>
    <child link="tyer_slave_left_axis4"/>
    <origin rpy="1.57075 0 0" xyz="-0.06 0.016 -0.03"/>
    <limit effort="100" velocity="100"/> 
    <joint_properties damping="0.0" friction="0.0"/>
  </joint>    
   
  <link name="right_board_front">
    <visual>
      <geometry>
        <box size="0.04 .002 .02"/>
      </geometry>
     </visual>
  </link>

  <joint name="right_board_to_right_board_front" type="fixed">
    <parent link="right_board"/>
    <child link="right_board_front"/>
    <origin xyz="0.095 0.0 0.0"/>
  </joint>
  
  <link name="left_board_front">
    <visual>
      <geometry>
        <box size="0.04 .002 .02"/>
      </geometry>
     </visual>
  </link>

  <joint name="left_board_to_left_board_front" type="fixed">
    <parent link="left_board"/>
    <child link="left_board_front"/>
    <origin xyz="0.095 0.0 0.0"/>
  </joint>
  
  <link name="tyer_slave_right_axis5">
    <visual>
      <geometry>
       <cylinder length=".03" radius="0.003"/>
      </geometry>
      <material name="yellow">
          <color rgba="1 1 0 1"/>
      </material>  
    </visual>
  </link>
 
  <joint name="right_leg_to_slave_right_axix5" type="continuous">
    <axis xyz="0 0 1"/> 
    <parent link="right_board_front"/>
    <child link="tyer_slave_right_axis5"/>
    <origin rpy="1.57075 0 0" xyz="0.005 -0.016 0.0"/>
    <limit effort="100" velocity="100"/> 
    <joint_properties damping="0.0" friction="0.0"/>
  </joint>    

  <link name="tyer_slave_left_axis5">
    <visual>
      <geometry>
       <cylinder length=".03" radius="0.003"/>
      </geometry>
      <material name="yellow">
          <color rgba="1 1 0 1"/>
      </material>  
    </visual>
  </link>

  <joint name="left_leg_to_slave_left_axix5" type="continuous">
    <axis xyz="0 0 1"/> 
    <parent link="left_board_front"/>
    <child link="tyer_slave_left_axis5"/>
    <origin rpy="1.57075 0 0" xyz="0.005 0.016 0.0"/>
    <limit effort="100" velocity="100"/> 
    <joint_properties damping="0.0" friction="0.0"/>
  </joint> 
  
  <link name="left_board_back">
    <visual>
      <geometry>
        <box size="0.05 .002 .024"/>
      </geometry>
     </visual>
  </link>

  <joint name="base_to_left_leg_back" type="fixed">
    <parent link="left_board"/>
    <child link="left_board_back"/>
    <origin xyz="-0.1 0.0 -0.005"/>
  </joint>

  <link name="right_board_back">
    <visual>
      <geometry>
        <box size="0.05 .002 .024"/>
      </geometry>
     </visual>
  </link>

  <joint name="base_to_right_leg_back" type="fixed">
    <parent link="right_board"/>
    <child link="right_board_back"/>
    <origin xyz="-0.1 0.0 -0.005"/>
  </joint>
  
  <link name="stick_left_motor">
    <visual>
      <origin rpy="0 0 0" xyz="0.015 0.0 0.0"/>
      <geometry>
       <box size="0.047 .048 .026"/>
      </geometry>
      <material name="black">
          <color rgba="0 0 0 1"/>
      </material>  
    </visual>
  </link>

  <joint name="left_board_to_stick_left_motor" type="fixed">
    <axis xyz="0 0 1"/> 
    <parent link="left_board_back"/>
    <child link="stick_left_motor"/>
    <origin rpy="0 0 0" xyz="0.0 -0.024 0.0"/>
    <limit effort="100" velocity="100"/> 
    <joint_properties damping="0.0" friction="0.0"/>
  </joint>
  <link name="stick_right_motor">
    <visual>
      <origin rpy="0 0 0" xyz="0.015 0.0 0.0"/>
      <geometry>
       <box size="0.047 .048 .026"/>
      </geometry>
      <material name="black">
          <color rgba="0 0 0 1"/>
      </material>  
    </visual>
  </link>

  <joint name="right_board_to_stick_right_motor" type="fixed">
    <axis xyz="0 0 1"/> 
    <parent link="right_board_back"/>
    <child link="stick_right_motor"/>
    <origin rpy="0 0 0" xyz="0.0 0.024 0.0"/>
    <limit effort="100" velocity="100"/> 
    <joint_properties damping="0.0" friction="0.0"/>
  </joint>
  
  <!--add stick: stick1: shortest stick2: mid stick3: longest-->
  <link name="left_stick1">
    <visual>
      <geometry>
       <cylinder length=".006" radius="0.002"/>
      </geometry>
      <material name="yellow">
          <color rgba="1 1 0 1"/>
      </material>  
    </visual>
  </link>

  <joint name="left_board_back_to_left_stick1" type="revolute">
    <axis xyz="0 0 1"/>
    <limit effort="1000.0" lower="0.0" upper="-4.24" velocity="0.5"/>
    <parent link="left_board_back"/>
    <child link="left_stick1"/>
    <origin rpy="-1.57075 0 0" xyz="0.0 0.004 0.0"/>
    <limit effort="100" velocity="100"/> 
    <joint_properties damping="0.0" friction="0.0"/>
  </joint>
  
  <link name="left_stick2">
    <visual>
      <geometry>
       <cylinder length=".054" radius="0.002"/>
      </geometry>
      <material name="yellow">
          <color rgba="1 1 0 1"/>
      </material>  
    </visual>
  </link>

  <joint name="left_stick1_to_left_stick2" type="fixed">
    <axis xyz="0 0 1"/> 
    <parent link="left_stick1"/>
    <child link="left_stick2"/>
    <origin rpy="1.57075 0 0" xyz="0.0 -0.027 0.003"/>
    <limit effort="100" velocity="100"/> 
    <joint_properties damping="0.0" friction="0.0"/>
  </joint>
   
  <link name="left_stick3">
    <visual>
      <geometry>
       <cylinder length=".207" radius="0.002"/>
      </geometry>
      <material name="yellow">
          <color rgba="1 1 0 1"/>
      </material>  
    </visual>
  </link>

  <joint name="left_stick2_to_left_stick3" type="fixed">
    <axis xyz="0 0 1"/> 
    <parent link="left_stick2"/>
    <child link="left_stick3"/>
    <origin rpy="0 1.57075 0" xyz="0.1035 0.0 0.027"/>
    <limit effort="100" velocity="100"/> 
    <joint_properties damping="0.0" friction="0.0"/>
  </joint>
  
  <link name="right_stick1">
    <visual>
      <geometry>
       <cylinder length=".006" radius="0.002"/>
      </geometry>
      <material name="yellow">
          <color rgba="1 1 0 1"/>
      </material>  
    </visual>
  </link>

  <joint name="right_board_back_to_right_stick1" type="revolute">
    <axis xyz="0 0 1"/>
    <limit effort="1000.0" lower="0.0" upper="4.24" velocity="0.5"/>
    <parent link="right_board_back"/>
    <child link="right_stick1"/>
    <origin rpy="1.57075 0 0" xyz="0.0 -0.004 0.0"/>
    <limit effort="100" velocity="100"/> 
    <joint_properties damping="0.0" friction="0.0"/>
  </joint>
  
  <link name="right_stick2">
    <visual>
      <geometry>
       <cylinder length=".054" radius="0.002"/>
      </geometry>
      <material name="yellow">
          <color rgba="1 1 0 1"/>
      </material>  
    </visual>
  </link>

  <joint name="right_stick1_to_right_stick2" type="fixed">
    <axis xyz="0 0 1"/> 
    <parent link="right_stick1"/>
    <child link="right_stick2"/>
    <origin rpy="-1.57075 0 0" xyz="0.0 0.027 0.003"/>
    <limit effort="100" velocity="100"/> 
    <joint_properties damping="0.0" friction="0.0"/>
  </joint>
   
  <link name="right_stick3">
    <visual>
      <geometry>
       <cylinder length=".207" radius="0.002"/>
      </geometry>
      <material name="yellow">
          <color rgba="1 1 0 1"/>
      </material>  
    </visual>
  </link>

  <joint name="right_stick2_to_right_stick3" type="fixed">
    <axis xyz="0 0 1"/> 
    <parent link="right_stick2"/>
    <child link="right_stick3"/>
    <origin rpy="0 1.57075 0" xyz="0.1035 0.0 0.027"/>
    <limit effort="100" velocity="100"/> 
    <joint_properties damping="0.0" friction="0.0"/>
  </joint>
  
   <link name="tyer_master_left">
    <visual>
      <geometry>
       <cylinder length=".035" radius="0.018"></cylinder>
      </geometry>
      <material name="green">
          <color rgba="0 1 0 1"/>
      </material>  
    </visual>
  </link>

  <joint name="tyer_master_left_axis_to_master_left" type="fixed">
    <axis xyz="0 0 1"/> 
    <parent link="tyer_master_left_axis"/>
    <child link="tyer_master_left"/>
    <origin rpy="0 0 0" xyz="0.0 0.0 -0.015"/>
    <limit effort="100" velocity="100"/> 
    <joint_properties damping="0.0" friction="0.0"/>
  </joint>  

  <link name="tyer_master_right">
    <visual>
      <geometry>
       <cylinder length=".035" radius="0.018"></cylinder>
      </geometry>
      <material name="green"/>
    </visual>
  </link>

  <joint name="right_leg_to_master_right" type="fixed">
    <axis xyz="0 0 1"/> 
    <parent link="tyer_master_right_axis"/>
    <child link="tyer_master_right"/>
    <origin rpy="0 0 0" xyz="0.0 0.0 0.015"/>
    <limit effort="100" velocity="100"/> 
    <joint_properties damping="0.0" friction="0.0"/>
  </joint>
         

  <link name="tyer_slave2_left">
    <visual>
      <geometry>
       <cylinder length=".027" radius="0.02"></cylinder>
      </geometry>
      <material name="green"/>
    </visual>
  </link>

  <joint name="left_leg_to_slave2_left" type="fixed">
    <axis xyz="0 0 1"/> 
    <parent link="tyer_slave_left_axis2"/>
    <child link="tyer_slave2_left"/>
    <origin rpy="0 0 0" xyz="0.0 0.0 -0.015"/>
    <limit effort="100" velocity="100"/> 
    <joint_properties damping="0.0" friction="0.0"/>
  </joint>  

  <link name="tyer_slave3_left">
    <visual>
      <geometry>
       <cylinder length=".027" radius="0.02"></cylinder>
      </geometry>
      <material name="green"/>
    </visual>
  </link>

  <joint name="left_leg_to_slave3_left" type="fixed">
    <axis xyz="0 0 1"/> 
    <parent link="tyer_slave_left_axis3"/>
    <child link="tyer_slave3_left"/>
    <origin rpy="0 0 0" xyz="0.0 0.0 -0.015"/>
    <limit effort="100" velocity="100"/> 
    <joint_properties damping="0.0" friction="0.0"/>
  </joint>   

  <link name="tyer_slave4_left">
    <visual>
      <geometry>
       <cylinder length=".027" radius="0.02"></cylinder>
      </geometry>
      <material name="green"/>
    </visual>
  </link>

  <joint name="left_leg_to_slave4_left" type="fixed">
    <axis xyz="0 0 1"/> 
    <parent link="tyer_slave_left_axis4"/>
    <child link="tyer_slave4_left"/>
    <origin rpy="0 0 0" xyz="0.0 0.0 -0.015"/>
    <limit effort="100" velocity="100"/> 
    <joint_properties damping="0.0" friction="0.0"/>
  </joint>    

  <link name="tyer_slave5_left">
    <visual>
      <geometry>
       <cylinder length=".027" radius="0.02"></cylinder>
      </geometry>
      <material name="green"/>
    </visual>
  </link>

  <joint name="left_leg_to_slave5_left" type="fixed">
    <axis xyz="0 0 1"/> 
    <parent link="tyer_slave_left_axis5"/>
    <child link="tyer_slave5_left"/>
    <origin rpy="0 0 0" xyz="0.0 0.0 -0.015"/>
    <limit effort="100" velocity="100"/> 
    <joint_properties damping="0.0" friction="0.0"/>
  </joint>           


  <link name="tyer_slave2_right">
    <visual>
      <geometry>
       <cylinder length=".027" radius="0.02"></cylinder>
      </geometry>
      <material name="green"/>
    </visual>
  </link>

  <joint name="right_leg_to_slave2_right" type="fixed">
    <axis xyz="0 0 1"/> 
    <parent link="tyer_slave_right_axis2"/>
    <child link="tyer_slave2_right"/>
    <origin rpy="0 0 0" xyz="0.0 0.0 0.015"/>
    <limit effort="100" velocity="100"/> 
    <joint_properties damping="0.0" friction="0.0"/>
  </joint>      


  <link name="tyer_slave3_right">
    <visual>
      <geometry>
       <cylinder length=".027" radius="0.02"></cylinder>
      </geometry>
      <material name="green"/>
    </visual>
  </link>

  <joint name="right_leg_to_slave3_right" type="fixed">
    <axis xyz="0 0 1"/> 
    <parent link="tyer_slave_right_axis3"/>
    <child link="tyer_slave3_right"/>
    <origin rpy="0 0 0" xyz="0.0 0.0 0.015"/>
    <limit effort="100" velocity="100"/> 
    <joint_properties damping="0.0" friction="0.0"/>
  </joint>   

  <link name="tyer_slave4_right">
    <visual>
      <geometry>
       <cylinder length=".027" radius="0.02"></cylinder>
      </geometry>
      <material name="green"/>
    </visual>
  </link>

  <joint name="right_leg_to_slave4_right" type="fixed">
    <axis xyz="0 0 1"/> 
    <parent link="tyer_slave_right_axis4"/>
    <child link="tyer_slave4_right"/>
    <origin rpy="0 0 0" xyz="0.0 0.0 0.015"/>
    <limit effort="100" velocity="100"/> 
    <joint_properties damping="0.0" friction="0.0"/>
  </joint>    

  <link name="tyer_slave5_right">
    <visual>
      <geometry>
       <cylinder length=".027" radius="0.02"></cylinder>
      </geometry>
      <material name="green"/>
    </visual>
  </link>

  <joint name="right_leg_to_slave5_right" type="fixed">
    <axis xyz="0 0 1"/> 
    <parent link="tyer_slave_right_axis5"/>
    <child link="tyer_slave5_right"/>
    <origin rpy="0 0 0" xyz="0.0 0.0 0.015"/>
    <limit effort="100" velocity="100"/> 
    <joint_properties damping="0.0" friction="0.0"/>
  </joint>
  
</robot>
